Workbook

Sheet Jan24
A1: DATE | B1: TIME | C1: PAIR | D1: TRADE IMAGE | E1: TYPE | F1: RESULT | G1: GROWTH % | H1: Comments
A2: 45300 | B2: 8-9am | C2: EUR/USD | D2: https://www.tradingview.com/x/vtN8sFpD/ | E2: SELL | F2: WON | G2: 0.02
A3: 45301 | B3: 8-9am | C3: EUR/USD | D3: https://www.tradingview.com/x/z7tOmJsU/ | E3: SELL | F3: LOST | G3: -0.01
A4: 45301 | B4: 8-9am | C4: EUR/USD | D4: https://www.tradingview.com/x/z7tOmJsU/ | E4: BUY | F4: WON | G4: 0.02
A5: 45302 | B5: 8-9am | C5: EUR/USD | D5: https://www.tradingview.com/x/WNsyiK26/ | E5: BUY | F5: LOST | G5: -0.01
A6: 45302 | B6: 8-9am | C6: EUR/USD | D6: https://www.tradingview.com/x/WNsyiK26/ | E6: SELL | F6: WON | G6: 0.02
A7: 45303 | B7: 8-9am | C7: EUR/USD | D7: https://www.tradingview.com/x/FORtAApX/ | E7: SELL | F7: LOST | G7: -0.01
A8: 45307 | B8: 8-9am | C8: EUR/USD | D8: https://www.tradingview.com/x/7NiKpuQ6/ | E8: SELL | F8: LOST | G8: -0.01
A9: 45307 | B9: 8-9am | C9: EUR/USD | D9: https://www.tradingview.com/x/7NiKpuQ6/ | E9: SELL | F9: WON | G9: 0.02
A10: 45308 | B10: 8-9am | C10: EUR/USD | D10: https://www.tradingview.com/x/LxOrH8Nk/ | E10: BUY | F10: LOST | G10: -0.01
A11: 45308 | B11: 8-9am | C11: EUR/USD | D11: https://www.tradingview.com/x/LxOrH8Nk/ | E11: SELL | F11: WON | G11: 0.02
A12: 45309 | B12: 8-9am | C12: EUR/USD | D12: https://www.tradingview.com/x/NAS8f75M/ | E12: SELL | F12: WON | G12: 0.02
A13: 45310 | B13: 8-9am | C13: EUR/USD | D13: https://www.tradingview.com/x/TotZrkut/ | E13: SELL | F13: WON | G13: 0.02
... A19: 45322 | B19: 3-4pm | C19: EUR/USD | D19: https://www.tradingview.com/x/fcnSMPA0 | E19: SELL | F19: WON | G19: 0.02
C29: DO NOT EDIT THE FIELDS INSIDE THIS YELLOW BOX
D30: Total Number of Winning Trades | E30: =COUNTIF(F2:F28,"WON") -> 10
D31: Total Number of Losing Trades | E31: =COUNTIF(F2:F28,"LOST") -> 8
D32: Total Number of Live Trades | E32: =SUM(E30:E31) -> 18
D33: Total Percentage Profit of Current Month | E33: =SUM(G2:G28) -> 0.12
D34: Monthly Percentage Profit Target | E34: ='Data Calcs'!$S$2 -> 0.1 | F34: =IF(E33>=E34,"ACHIEVED","") -> ACHIEVED
A38: USE THE AREA BELOW FOR TRAINING PURPOSES USING A DEMO ACCOUNT
A39: DATE | B39: TIME | C39: PAIR | D39: TRADE IMAGE | E39: TYPE | F39: RESULT | G39: GROWTH %
A40: Mon 08/01/2024 | B40: 8-9am | C40: EUR/USD | D40: https://www.tradingview.com/x/bh1z3kJS/ | F40: WON | G40: 0.02
A41: Mon 08/01/2024 | B41: 3-4pm | C41: EUR/USD | D41: https://www.tradingview.com/x/oP2kIPbC/ | F41: WON | G41: 0.02
A42: Tue 09/01/2024 | B42: 3-4pm | C42: EUR/USD | D42: https://www.tradingview.com/x/opCayPrg/ | F42: LOST | G42: -0.01
A43: Tue 09/01/2024 | B43: 3-4pm | C43: EUR/USD | D43: https://www.tradingview.com/x/opCayPrg/ | F43: WON | G43: 0.02
A44: Wed 10/01/2024 | B44: 3-4pm | C44: EUR/USD | D44: https://www.tradingview.com/x/L0D5EizQ/ | F44: WON | G44: 0.02
A45: Fri 12/01/2024 | B45: 3-4pm | C45: EUR/USD | D45: https://www.tradingview.com/x/6EcVenB1/ | F45: LOST | G45: -0.01
A46: Fri 12/01/2024 | B46: 3-4pm | C46: EUR/USD | D46: https://www.tradingview.com/x/6EcVenB1/ | F46: WON | G46: 0.02
A47: Mon 15/01/2024 | B47: 3-4pm | C47: EUR/USD | D47: https://www.tradingview.com/x/UQDXffZ6/ | F47: LOST | G47: -0.01
A48: Mon 15/01/2024 | B48: 3-4pm | C48: EUR/USD | D48: https://www.tradingview.com/x/UQDXffZ6/ | F48: LOST | G48: -0.01
A49: Tue 16/01/2024 | B49: 3-4pm | C49: EUR/USD | D49: https://www.tradingview.com/x/z3gsH1ck/ | F49: LOST | G49: -0.01
A50: Wed 17/01/2024 | B50: 3-4pm | C50: EUR/USD | D50: https://www.tradingview.com/x/EN05Cjiw/ | F50: WON | G50: 0.02
A51: Thu 18/01/2024 | B51: 3-4pm | C51: EUR/USD | D51: https://www.tradingview.com/x/zwJvbNIo/ | F51: WON | G51: 0.02
... A60: Mon 29/01/2024 | B60: 3-4pm | C60: EUR/USD | D60: https://www.tradingview.com/x/CtbgZrbv/ | F60: LOST | G60: -0.01
A61: Mon 29/01/2025 | B61: 1-2pm | C61: EUR/USD | D61: https://www.tradingview.com/x/R3B4Gj4y/ | E61: BUY | F61: WON | G61: 0.005 | H61: turned sl into sp but price reached 2%
C91: TRADING RESULTS
D92: DO NOT EDIT THE FIELDS INSIDE THIS YELLOW BOX
C93: Live Trades
D94: Total Number of Winning Live Trades | E94: =COUNTIF(F2:F28,"WON") -> 10
...

Sheet Feb24
A1: DATE | B1: TIME | C1: PAIR | D1: TRADE IMAGE | E1: TYPE | F1: RESULT | G1: GROWTH % | H1: Comments
A2: Tue 06/02/2024 | B2: 8-9am | C2: EUR/USD | D2: https://www.tradingview.com/x/lCwbhJVT/ | E2: BUY | F2: LOST | G2: -0.01
A3: Tue 06/02/2024 | B3: 8-9am | C3: EUR/USD | D3: https://www.tradingview.com/x/lCwbhJVT/ | E3: SELL | F3: WON | G3: 0.02
A4: Wed 07/02/2024 | B4: 8-9am | C4: EUR/USD | D4: https://www.tradingview.com/x/aT6G5yiO/ | E4: SELL | F4: WON | G4: 0.02
A5: Thu 08/02/2024 | B5: 8-9am | C5: EUR/USD | D5: https://www.tradingview.com/x/wXv2F2YD/ | E5: SELL | F5: WON | G5: 0.02
A6: Fri 09/02/2024 | B6: 8-9am | C6: EUR/USD | D6: https://www.tradingview.com/x/2xZCGfhW/ | E6: SELL | F6: WON | G6: 0.02
A7: Tue 13/02/2024 | B7: 8-9am | C7: EUR/USD | D7: https://www.tradingview.com/x/yWosWJ8X/ | E7: BUY | F7: LOST | G7: -0.01 | H7: market showing too much consolidation
A8: Tue 13/02/2024 | B8: 8-9am | C8: EUR/USD | D8: https://www.tradingview.com/x/yWosWJ8X/ | E8: SELL | F8: LOST | G8: -0.01 | H8: hit stop loss just over 0.003 pips then went to hit tp
A9: Wed 14/02/2024 | B9: 8-9am | C9: EUR/USD | D9: https://www.tradingview.com/x/bgXByCFW/ | E9: BUY | F9: WON | G9: 0.02
A10: Thu 15/02/2024 | B10: 8-9am | C10: EUR/USD | D10: https://www.tradingview.com/x/I9XnO7p5/ | E10: BUY | F10: LOST | G10: -0.01
A11: Thu 15/02/2024 | B11: 8-9am | C11: EUR/USD | D11: https://www.tradingview.com/x/I9XnO7p5/ | E11: SELL | F11: WON | G11: 0.02
A12: Fri 16/02/2024 | B12: 8-9am | C12: EUR/USD | D12: https://www.tradingview.com/x/wILizbgk/ | E12: SELL | F12: LOST | G12: -0.01
A13: Fri 16/02/2024 | B13: 8-9am | C13: EUR/USD | D13: https://www.tradingview.com/x/wILizbgk/ | E13: BUY | F13: WON | G13: 0.02
A14: Tue 20/02/2024 | B14: 8-9am | C14: EUR/USD | D14: https://www.tradingview.com/x/jPAeXu9A/ | E14: BUY | F14: LOST | G14: -0.01 | H14: Due to technical issues unable to use MT4
A15: Tue 20/02/2024 | B15: 8-9am | C15: EUR/USD | D15: https://www.tradingview.com/x/jPAeXu9A/ | E15: SELL | F15: LOST | G15: -0.01 | H15: Due to technical issues unable to use MT4
A16: Tue 20/02/2024 | B16: 8-9am | C16: EUR/USD | D16: https://www.tradingview.com/x/nAEA28AV/ | E16: SELL | F16: LOST | G16: -0.01 | H16: Hit Stop loss just over by 0.05 pips then went on to hit TP
A17: Tue 20/02/2024 | B17: 8-9am | C17: EUR/USD | D17: https://www.tradingview.com/x/nAEA28AV/ | E17: SELL | F17: LOST | G17: -0.01
A18: Wed 21/02/2024 | B18: 8-9am | C18: EUR/USD | D18: https://www.tradingview.com/x/IpmC0m7R/ | E18: SELL | F18: WON | G18: 0.02
A19: Fri 23/02/2024 | B19: 8-9am | C19: EUR/USD | D19: https://www.tradingview.com/x/D8LHk3HM/ | E19: BUY | F19: LOST | G19: -0.01
A20: Fri 23/02/2024 | B20: 8-9am | C20: EUR/USD | D20: https://www.tradingview.com/x/D8LHk3HM/ | E20: SELL | F20: WON | G20: 0.02
A21: 45349 | B21: 8-9am | C21: EUR/USD | D21: https://www.tradingview.com/x/CIofKiw5/ | E21: BUY | F21: WON | G21: 0.02
A22: 45350 | B22: 8-9am | C22: EUR/USD | D22: https://www.tradingview.com/x/GaQCU7LE/ | E22: SELL | F22: WON | G22: 0.02
C29: DO NOT EDIT THE FIELDS INSIDE THIS YELLOW BOX
D30: Total Number of Winning Trades | E30: =COUNTIF(F2:F28,"WON") -> 11
D31: Total Number of Losing Trades | E31: =COUNTIF(F2:F28,"LOST") -> 10
D32: Total Number of Live Trades | E32: =SUM(E30:E31) -> 21
D33: Total Percentage Profit of Current Month | E33: =SUM(G2:G28) -> 0.12
D34: Monthly Percentage Profit Target | E34: ='Data Calcs'!$S$2 -> 0.1 | F34: =IF(E33>=E34,"ACHIEVED","") -> ACHIEVED
A38: USE THE AREA BELOW FOR TRAINING PURPOSES USING A DEMO ACCOUNT
A39: DATE | B39: TIME | C39: PAIR | D39: TRADE IMAGE | E39: TYPE | F39: RESULT | G39: GROWTH %
C91: TRADING RESULTS
D92: DO NOT EDIT THE FIELDS INSIDE THIS YELLOW BOX
C93: Live Trades
D94: Total Number of Winning Live Trades | E94: =COUNTIF(F2:F28,"WON") -> 11
D95: Total Number of Losing Live Trades | E95: =COUNTIF(F2:F28,"LOST") -> 10
D96: Total Number of Live Trades | E96: =E94+E95 -> 21
D97: Total Percentage Profit of Live Trades | E97: =SUM(G2:G28) -> 0.12
D98: Monthly Percentage Profit Target | E98: ='Data Calcs'!$S$2 -> 0.1 | F98: =IF(E97>=E98,"ACHIEVED","") -> ACHIEVED
D99: Total Win Rate Live Trades | E99: =IFERROR((E94/E96),0) -> 0.52380952
C100: Demo Trades
...

Sheet Mar24
A1: DATE | B1: TIME | C1: PAIR | D1: TRADE IMAGE | E1: TYPE | F1: RESULT | G1: GROWTH % | H1: Comments
A2: 45356 | B2: 10-11am | C2: EUR/USD | D2: https://www.tradingview.com/x/0thUOoum/ | E2: BUY | F2: LOST | G2: -0.01
A3: 45357 | B3: 8-9am | C3: EUR/USD | D3: https://www.tradingview.com/x/1BsLBqi3/ | E3: BUY | F3: WON | G3: 0.02
A4: 45358 | B4: 8-9am | C4: EUR/USD | D4: https://www.tradingview.com/x/DgTheg4V/ | E4: BUY | F4: LOST | G4: -0.01
A5: 45364 | B5: 8-9am | C5: EUR/USD | D5: https://www.tradingview.com/x/gKguB9S3/ | E5: BUY | F5: LOST | G5: -0.01
A6: 45364 | B6: 7-8pm | C6: US100 | D6: https://www.tradingview.com/x/jsAx6VXf/ | E6: SELL | F6: WON | G6: 0.02
A7: 45365 | B7: 8-9am | C7: EUR/USD | D7: https://www.tradingview.com/x/0cRHAH58/ | E7: BUY | F7: LOST | G7: -0.01
A8: 45365 | B8: 8-9am | C8: EUR/USD | D8: https://www.tradingview.com/x/0cRHAH58/ | E8: SELL | F8: LOST | G8: -0.01
A9: 45366 | B9: 8-9am | C9: EUR/USD | D9: https://www.tradingview.com/x/opTp4LLH/ | E9: BUY | F9: WON | G9: 0.02
A10: 45369 | B10: 7-8pm | C10: US100 | D10: https://www.tradingview.com/x/YPYePQ9D/ | E10: SELL | F10: WON | G10: 0.02
A11: 45372 | B11: 7-8pm | C11: US100 | D11: https://www.tradingview.com/x/Xiu4PCES/ | E11: SELL | F11: LOST | G11: -0.01
A12: 45373 | B12: 8-9am | C12: EUR/USD | D12: https://www.tradingview.com/x/ogpDsr5V/ | E12: SELL | F12: WON | G12: 0.02
A13: 45377 | B13: 8-9am | C13: EUR/USD | D13: https://www.tradingview.com/x/bhMy0CNV/ | E13: BUY | F13: WON | G13: 0.02
A14: 45378 | B14: 7-8pm | C14: US100 | D14: https://www.tradingview.com/x/7CGPFKKl/ | E14: BUY | F14: WON | G14: 0.02
C30: DO NOT EDIT THE FIELDS INSIDE THIS YELLOW BOX
D31: Total Number of Winning Trades | E31: =COUNTIF(F2:F29,"WON") -> 7
D32: Total Number of Losing Trades | E32: =COUNTIF(F2:F29,"LOST") -> 6
D33: Total Number of Live Trades | E33: =SUM(E31:E32) -> 13
D34: Total Percentage Profit of Current Month | E34: =SUM(G2:G29) -> 0.08
D35: Monthly Percentage Profit Target | E35: ='Data Calcs'!$S$2 -> 0.1 | F35: =IF(E34>=E35,"ACHIEVED","")
A39: USE THE AREA BELOW FOR TRAINING PURPOSES USING A DEMO ACCOUNT
A40: DATE | B40: TIME | C40: PAIR | D40: TRADE IMAGE | E40: TYPE | F40: RESULT | G40: GROWTH %
C92: TRADING RESULTS
D93: DO NOT EDIT THE FIELDS INSIDE THIS YELLOW BOX
C94: Live Trades
D95: Total Number of Winning Live Trades | E95: =COUNTIF(F2:F29,"WON") -> 7
D96: Total Number of Losing Live Trades | E96: =COUNTIF(F2:F29,"LOST") -> 6
D97: Total Number of Live Trades | E97: =E95+E96 -> 13
D98: Total Percentage Profit of Live Trades | E98: =SUM(G2:G29) -> 0.08
D99: Monthly Percentage Profit Target | E99: ='Data Calcs'!$S$2 -> 0.1 | F99: =IF(E98>=E99,"ACHIEVED","")
D100: Total Win Rate Live Trades | E100: =IFERROR((E95/E97),0) -> 0.53846154
C101: Demo Trades
D102: Total Number of Winning Demo Trades | E102: =COUNTIF(F41:F91,"WON") -> 0
D103: Total Number of Losing Demo Trades | E103: =COUNTIF(F41:F91,"LOST") -> 0
D104: Total Number of Demo Trades | E104: =E102+E103 -> 0
D105: Total Percentage Profit of Demo Trades | E105: =SUM(G40:G91) -> 0
D106: Total Win Rate Live Trades | E106: =IFERROR((E102/E104),0) -> 0
C107: Combined Live & Demo Trades
D108: Total Number of Winning Trades | E108: =E102+E95 -> 7
D109: Total Number of Losing Trades | E109: =E103+E96 -> 6
...

Sheet Apr24
A1: DATE | B1: TIME | C1: PAIR | D1: TRADE IMAGE | E1: TYPE | F1: RESULT | G1: GROWTH % | H1: Comments
A2: 45384 | B2: 7-8pm | C2: US100 | D2: https://www.tradingview.com/x/TS2GdqON/ | E2: BUY | F2: LOST | G2: -0.01
A3: 45384 | B3: 7-8pm | C3: US100 | D3: https://www.tradingview.com/x/TS2GdqON/ | E3: SELL | F3: LOST | G3: -0.01
A4: 45385 | B4: 7-8pm | C4: US100 | D4: https://www.tradingview.com/x/aqdlsyJT/ | E4: SELL | F4: LOST | G4: -0.01
A5: 45386 | B5: 3-4pm | C5: EUR/USD | D5: https://www.tradingview.com/x/F5KkGzwQ/ | E5: BUY | F5: LOST | G5: -0.01
A6: 45390 | B6: 8-9am | C6: EUR/USD | D6: https://www.tradingview.com/x/8mvQD0A9/ | E6: BUY | F6: LOST | G6: -0.01
A7: 45391 | B7: 8-9am | C7: EUR/USD | D7: https://www.tradingview.com/x/ZYaxsF7P/ | E7: BUY | F7: LOST | G7: -0.01
A8: 45392 | B8: 8-9am | C8: EUR/USD | D8: https://www.tradingview.com/x/oNNGMIkE/ | E8: BUY | F8: LOST | G8: -0.01
A9: 45397 | B9: 8-9am | C9: EUR/USD | D9: https://www.tradingview.com/x/htf2wPlv/ | E9: BUY | F9: LOST | G9: -0.01
A10: 45398 | B10: 8-9am | C10: EUR/USD | D10: https://www.tradingview.com/x/dTeCQmSW/ | E10: BUY | F10: LOST | G10: -0.01
A11: 45398 | B11: 8-9am | C11: EUR/USD | D11: https://www.tradingview.com/x/dTeCQmSW/ | E11: SELL | F11: LOST | G11: -0.01
A12: 45401 | B12: 11-12am | C12: EUR/USD | D12: https://www.tradingview.com/x/JnULC3zd/ | E12: SELL | F12: WON | G12: 0.02
A13: 45404 | B13: 9-10am | C13: EUR/USD | D13: https://www.tradingview.com/x/LXih7mHg/ | E13: SELL | F13: LOST | G13: -0.01
... A22: 45411 | B22: 7-8am | C22: EUR/USD | D22: https://www.tradingview.com/x/2mHpO5lK/ | E22: SELL | F22: WON | G22: 0.02
A23: 45412 | B23: 7-8am | C23: EUR/USD | D23: https://www.tradingview.com/x/R37MlB9B/ | F23: LOST | G23: -0.01
A24: 45412 | B24: 11-12am | C24: EUR/USD | D24: https://www.tradingview.com/x/ZH5JnIIi/ | E24: SELL | F24: WON | G24: 0.02
C27: DO NOT EDIT THE FIELDS INSIDE THIS YELLOW BOX
D28: Total Number of Winning Trades | E28: =COUNTIF(F2:F26,"WON") -> 8
D29: Total Number of Losing Trades | E29: =COUNTIF(F2:F26,"LOST") -> 15
D30: Total Number of Live Trades | E30: =SUM(E28:E29) -> 23
D31: Total Percentage Profit of Current Month | E31: =SUM(G2:G26) -> 0.01
D32: Monthly Percentage Profit Target | E32: ='Data Calcs'!$S$2 -> 0.1 | F32: =IF(E31>=E32,"ACHIEVED","")
A36: USE THE AREA BELOW FOR TRAINING PURPOSES USING A DEMO ACCOUNT
A37: DATE | B37: TIME | C37: PAIR | D37: TRADE IMAGE | E37: TYPE | F37: RESULT | G37: GROWTH %
C89: TRADING RESULTS
D90: DO NOT EDIT THE FIELDS INSIDE THIS YELLOW BOX
C91: Live Trades
D92: Total Number of Winning Live Trades | E92: =COUNTIF(F2:F26,"WON") -> 8
D93: Total Number of Losing Live Trades | E93: =COUNTIF(F2:F26,"LOST") -> 15
D94: Total Number of Live Trades | E94: =E92+E93 -> 23
D95: Total Percentage Profit of Live Trades | E95: =SUM(G2:G26) -> 0.01
D96: Monthly Percentage Profit Target | E96: ='Data Calcs'!$S$2 -> 0.1 | F96: =IF(E95>=E96,"ACHIEVED","")
D97: Total Win Rate Live Trades | E97: =IFERROR((E92/E94),0) -> 0.34782609
C98: Demo Trades
D99: Total Number of Winning Demo Trades | E99: =COUNTIF(F38:F88,"WON") -> 0
D100: Total Number of Losing Demo Trades | E100: =COUNTIF(F38:F88,"LOST") -> 0
D101: Total Number of Demo Trades | E101: =E99+E100 -> 0
D102: Total Percentage Profit of Demo Trades | E102: =SUM(G37:G88) -> 0
D103: Total Win Rate Live Trades | E103: =IFERROR((E99/E101),0) -> 0
C104: Combined Live & Demo Trades
...

Sheet May24
A1: DATE | B1: TIME | C1: PAIR | D1: TRADE IMAGE | E1: TYPE | F1: RESULT | G1: GROWTH % | H1: Comments
A2: 45414 | B2: 9-10am | C2: EUR/USD | D2: https://www.tradingview.com/x/Z8LO8R7q/ | E2: SELL | F2: WON | G2: 0.02
A3: 45415 | B3: 7-8am | C3: EUR/USD | D3: https://www.tradingview.com/x/UKQA9BG6/ | E3: SELL | F3: LOST | G3: -0.01
A4: 45415 | B4: 8-9am | C4: EUR/USD | D4: https://www.tradingview.com/x/UKQA9BG6/ | E4: SELL | F4: WON | G4: 0.02
A5: 45419 | B5: 8-9am | C5: EUR/USD | D5: https://www.tradingview.com/x/LBljX3lW/ | E5: SELL | F5: LOST | G5: -0.01
A6: 45419 | B6: 6-7pm | C6: US100 | D6: https://www.tradingview.com/x/mrbwdJYq/ | E6: SELL | F6: WON | G6: 0.02
A7: 45420 | B7: 8-9am | C7: EUR/USD | D7: https://www.tradingview.com/x/pbbif2nW/ | E7: SELL | F7: LOST | G7: -0.01 | H7: commission loss
A8: 45421 | B8: 3-4pm | C8: US100 | D8: https://www.tradingview.com/x/PouJyseP/ | E8: SELL | F8: LOST | G8: -0.01
A9: 45421 | B9: 7-8pm | C9: US100 | D9: https://www.tradingview.com/x/aPA33bjE/ | E9: BUY | F9: WON | G9: 0.02
A10: 45422 | B10: 8-9am | C10: EUR/USD | D10: https://www.tradingview.com/x/C8DYPyjQ/ | E10: BUY | F10: WON | G10: 0.01 | H10: Trade went on too long so took 1%
A11: 45425 | B11: 3-4pm | C11: US100 | D11: https://www.tradingview.com/x/2ddlu5n7/ | E11: SELL | F11: LOST | G11: -0.01
A12: 45427 | B12: 8-9am | C12: EUR/USD | D12: https://www.tradingview.com/x/byb9ZEG7/ | E12: BUY | F12: LOST | G12: -0.01
A13: 45427 | B13: 2-3pm | C13: US100 | D13: https://www.tradingview.com/x/GE9AsSrt/ | E13: SELL | F13: WON | G13: 0.02
A14: 45428 | B14: 8-9am | C14: EUR/USD | D14: https://www.tradingview.com/x/ScxTcZDY/ | E14: BUY | F14: LOST | G14: -0.01
A15: 45428 | B15: 2-3pm | C15: US100 | D15: https://www.tradingview.com/x/poxWdLdx/ | E15: BUY | F15: WON | G15: 0.02
A16: 45433 | B16: 8-9am | C16: EUR/USD | D16: https://www.tradingview.com/x/mWSdGNZv/ | E16: BUY | F16: LOST | G16: -0.01
A17: 45433 | B17: 3-4pm | C17: US100 | D17: https://www.tradingview.com/x/NRfcM9pv/ | E17: BUY | F17: WON | G17: 0.02
A18: 45434 | B18: 8-9am | C18: EUR/USD | D18: https://www.tradingview.com/x/g2nxeyEl/ | E18: SELL | F18: WON | G18: 0.02
A19: 45436 | B19: 8-9am | C19: EUR/USD | D19: https://www.tradingview.com/x/MHg4sdzc/ | E19: SELL | F19: LOST | G19: -0.01
A20: 45436 | B20: 8-9am | C20: EUR/USD | D20: https://www.tradingview.com/x/MHg4sdzc/ | E20: BUY | F20: LOST | G20: -0.01
A21: 45440 | B21: 8-9am | C21: EUR/USD | D21: https://www.tradingview.com/x/V3m68gG3/ | E21: SELL | F21: WON | G21: 0.02
A22: 45442 | B22: 8-9am | C22: EUR/USD | D22: https://www.tradingview.com/x/iZD1JpWf/ | E22: BUY | F22: WON | G22: 0.02
C29: DO NOT EDIT THE FIELDS INSIDE THIS YELLOW BOX
D30: Total Number of Winning Trades | E30: =COUNTIF(F2:F28,"WON") -> 11
D31: Total Number of Losing Trades | E31: =COUNTIF(F2:F28,"LOST") -> 10
D32: Total Number of Live Trades | E32: =SUM(E30:E31) -> 21
D33: Total Percentage Profit of Current Month | E33: =SUM(G2:G28) -> 0.11
D34: Monthly Percentage Profit Target | E34: ='Data Calcs'!$S$2 -> 0.1 | F34: =IF(E33>=E34,"ACHIEVED","") -> ACHIEVED
A38: USE THE AREA BELOW FOR TRAINING PURPOSES USING A DEMO ACCOUNT
A39: DATE | B39: TIME | C39: PAIR | D39: TRADE IMAGE | E39: TYPE | F39: RESULT | G39: GROWTH %
C91: TRADING RESULTS
D92: DO NOT EDIT THE FIELDS INSIDE THIS YELLOW BOX
C93: Live Trades
D94: Total Number of Winning Live Trades | E94: =COUNTIF(F2:F28,"WON") -> 11
D95: Total Number of Losing Live Trades | E95: =COUNTIF(F2:F28,"LOST") -> 10
D96: Total Number of Live Trades | E96: =E94+E95 -> 21
D97: Total Percentage Profit of Live Trades | E97: =SUM(G2:G28) -> 0.11
D98: Monthly Percentage Profit Target | E98: ='Data Calcs'!$S$2 -> 0.1 | F98: =IF(E97>=E98,"ACHIEVED","") -> ACHIEVED
D99: Total Win Rate Live Trades | E99: =IFERROR((E94/E96),0) -> 0.52380952
C100: Demo Trades
...

Sheet Jun24
A1: DATE | B1: TIME | C1: PAIR | D1: TRADE IMAGE | E1: TYPE | F1: RESULT | G1: GROWTH % | H1: Comments
A2: 45447 | B2: 10-11am | C2: EUR/USD | D2: https://www.tradingview.com/x/GjU8OwaT/ | E2: SELL | F2: WON | G2: 0.02
A3: 45449 | B3: 7-8pm | C3: US100 | D3: https://www.tradingview.com/x/slH3ETMi/ | E3: SELL | F3: WON | G3: 0.02 | H3: Highest price US100 has been so far
A4: 45450 | B4: 8-9am | C4: EUR/USD | D4: https://www.tradingview.com/x/p01gVGR1/ | E4: BUY | F4: LOST | G4: -0.01 | H4: Non Farm Payroll
A5: 45454 | B5: 8-9am | C5: EUR/USD | D5: https://www.tradingview.com/x/IDZg6YHE/ | E5: BUY | F5: LOST | G5: -0.01
A6: 45454 | B6: 10-11am | C6: EUR/USD | D6: https://www.tradingview.com/x/RCuSsI23/ | E6: BUY | F6: WON | G6: 0.02
A7: 45455 | B7: 8-9am | C7: EUR/USD | D7: https://www.tradingview.com/x/KppIzcLz/ | E7: BUY | F7: LOST | G7: -0.01
A8: 45455 | B8: 8-9am | C8: EUR/USD | D8: https://www.tradingview.com/x/KppIzcLz/ | E8: BUY | F8: WON | G8: 0.02
A9: 45456 | B9: 8-9am | C9: EUR/USD | D9: https://www.tradingview.com/x/ucNNwmh7/ | E9: SELL | F9: WON | G9: 0.02
A10: 45457 | B10: 8-9am | C10: EUR/USD | D10: https://www.tradingview.com/x/a0Zohuan/ | E10: BUY | F10: LOST | G10: -0.01
A11: 45457 | B11: 8-9am | C11: EUR/USD | D11: https://www.tradingview.com/x/a0Zohuan/ | E11: SELL | F11: WON | G11: 0.02
A12: 45460 | B12: 8-9am | C12: EUR/USD | D12: https://www.tradingview.com/x/lKsCWtf0/ | E12: SELL | F12: WON | G12: 0.015 | H12: decided to tp on psar flip and Monday morning
A13: 45461 | B13: 8-9am | C13: EUR/USD | D13: https://www.tradingview.com/x/ObjHfUD4/ | E13: SELL | F13: WON | G13: 0.02
C29: DO NOT EDIT THE FIELDS INSIDE THIS YELLOW BOX
D30: Total Number of Winning Trades | E30: =COUNTIF(F2:F28,"WON") -> 8
D31: Total Number of Losing Trades | E31: =COUNTIF(F2:F28,"LOST") -> 4
D32: Total Number of Live Trades | E32: =SUM(E30:E31) -> 12
D33: Total Percentage Profit of Current Month | E33: =SUM(G2:G28) -> 0.115
D34: Monthly Percentage Profit Target | E34: ='Data Calcs'!$S$2 -> 0.1 | F34: =IF(E33>=E34,"ACHIEVED","") -> ACHIEVED
A38: USE THE AREA BELOW FOR TRAINING PURPOSES USING A DEMO ACCOUNT
A39: DATE | B39: TIME | C39: PAIR | D39: TRADE IMAGE | E39: TYPE | F39: RESULT | G39: GROWTH %
A40: 45463 | B40: 8-9am | C40: EUR/USD | D40: https://www.tradingview.com/x/LxJLmB5r/ | E40: SELL | F40: WON | G40: 0.02
A41: 45468 | B41: 8-9am | C41: EUR/USD | D41: https://www.tradingview.com/x/2wRpomyi/ | E41: BUY | F41: WON | G41: 0.0073
A42: 45469 | B42: 8-9am | C42: EUR/USD | D42: https://www.tradingview.com/x/lE9O4KmE/ | E42: BUY | F42: WON | G42: 0.02
A43: 45470 | B43: 8-9am | C43: EUR/USD | D43: https://www.tradingview.com/x/K3Y3x89l/ | E43: BUY | G43: 0 | H43: Break Even
C91: TRADING RESULTS
D92: DO NOT EDIT THE FIELDS INSIDE THIS YELLOW BOX
C93: Live Trades
D94: Total Number of Winning Live Trades | E94: =COUNTIF(F2:F28,"WON") -> 8
D95: Total Number of Losing Live Trades | E95: =COUNTIF(F2:F28,"LOST") -> 4
D96: Total Number of Live Trades | E96: =E94+E95 -> 12
D97: Total Percentage Profit of Live Trades | E97: =SUM(G2:G28) -> 0.115
D98: Monthly Percentage Profit Target | E98: ='Data Calcs'!$S$2 -> 0.1 | F98: =IF(E97>=E98,"ACHIEVED","") -> ACHIEVED
D99: Total Win Rate Live Trades | E99: =IFERROR((E94/E96),0) -> 0.66666667
C100: Demo Trades
D101: Total Number of Winning Demo Trades | E101: =COUNTIF(F40:F90,"WON") -> 3
D102: Total Number of Losing Demo Trades | E102: =COUNTIF(F40:F90,"LOST") -> 0
D103: Total Number of Demo Trades | E103: =E101+E102 -> 3
D104: Total Percentage Profit of Demo Trades | E104: =SUM(G39:G90) -> 0.0473
D105: Total Win Rate Live Trades | E105: =IFERROR((E101/E103),0) -> 1
...

Sheet Jul24
A1: DATE | B1: TIME | C1: PAIR | D1: TRADE IMAGE | E1: TYPE | F1: RESULT | G1: GROWTH % | H1: Comments
A2: 45474 | B2: 7-8am | C2: EUR/USD | D2: https://www.tradingview.com/x/QOa47Frl/ | E2: SELL | F2: LOST | G2: -0.01
A3: 45474 | B3: 7-8am | C3: EUR/USD | D3: https://www.tradingview.com/x/QOa47Frl/ | E3: SELL | G3: 0 | H3: BREAKEVEN
A4: 45475 | B4: 7-8am | C4: EUR/USD | D4: https://www.tradingview.com/x/zD8ZANvK/ | E4: SELL | F4: WON | G4: 0.015 | H4: Hit TP 2%
A5: 45476 | B5: 7-8am | C5: EUR/USD | D5: https://www.tradingview.com/x/xDezAMGw/ | E5: BUY | F5: LOST | G5: -0.01
A6: 45476 | B6: 7-8am | C6: EUR/USD | D6: https://www.tradingview.com/x/xDezAMGw/ | E6: BUY | F6: WON | G6: 0.017 | H6: Hit TP 2%
A7: 45482 | B7: 8-9am | C7: EUR/USD | D7: https://www.tradingview.com/x/BFyQDCfW/ | E7: BUY | F7: LOST | G7: -0.01 | H7: risky volume still low
A8: 45482 | B8: 8-9am | C8: EUR/USD | D8: https://www.tradingview.com/x/BFyQDCfW/ | E8: SELL | F8: WON | G8: 0.02 | H8: very cautious
A9: 45483 | B9: 8-9am | C9: EUR/USD | D9: https://www.tradingview.com/x/aCO5XI4a/ | E9: SELL | F9: LOST | G9: -0.01 | H9: just stopped out by stop loss being in wrong position
A10: 45483 | B10: 8-9am | C10: EUR/USD | D10: https://www.tradingview.com/x/O9oDATj6/ | E10: BUY | F10: WON | G10: 0.02
A11: 45484 | B11: 8-9am | C11: EUR/USD | D11: https://www.tradingview.com/x/GFWMPNJz/ | E11: BUY | F11: WON | G11: 0.01 | H11: went 2% TP
A12: 45490 | B12: 8-9am | C12: EUR/USD | D12: https://www.tradingview.com/x/RvXVTYXX/ | E12: BUY | F12: WON | G12: 0.02
A13: 45491 | B13: 8-9am | C13: EUR/USD | D13: https://www.tradingview.com/x/XQ5wDMVG/ | E13: BUY | G13: 0 | H13: breakeven
A14: 45491 | B14: 8-9am | C14: EUR/USD | D14: https://www.tradingview.com/x/XQ5wDMVG/ | E14: SELL | F14: LOST | G14: -0.01
A15: 45496 | B15: 8-9am | C15: EUR/USD | D15: https://www.tradingview.com/x/4F9qdXdu/ | E15: BUY | G15: 0 | H15: Would Have lost
A16: 45496 | B16: 8-9am | C16: EUR/USD | D16: https://www.tradingview.com/x/4F9qdXdu/ | E16: SELL | F16: WON | G16: 0.01 | H16: Would have hit TP
A17: 45497 | B17: 10-11am | C17: EUR/USD | D17: https://www.tradingview.com/x/TUNhbTDl/ | E17: SELL | F17: LOST | G17: -0.01
A18: 45498 | B18: 8-9am | C18: EUR/USD | D18: https://www.tradingview.com/x/Gnpbhg7y/ | E18: BUY | F18: WON | G18: 0.02
A19: 45499 | B19: 8-9am | C19: EUR/USD | D19: https://www.tradingview.com/x/M6zfPO6A/ | E19: BUY | F19: LOST | G19: -0.01
A20: 45499 | B20: 8-9am | C20: EUR/USD | D20: https://www.tradingview.com/x/M6zfPO6A/ | E20: SELL | F20: LOST | G20: -0.01
C29: DO NOT EDIT THE FIELDS INSIDE THIS YELLOW BOX
D30: Total Number of Winning Trades | E30: =COUNTIF(F2:F28,"WON") -> 8
D31: Total Number of Losing Trades | E31: =COUNTIF(F2:F28,"LOST") -> 8
D32: Total Number of Live Trades | E32: =SUM(E30:E31) -> 16
D33: Total Percentage Profit of Current Month | E33: =SUM(G2:G28) -> 0.052
D34: Monthly Percentage Profit Target | E34: ='Data Calcs'!$S$2 -> 0.1 | F34: =IF(E33>=E34,"ACHIEVED","")
A38: USE THE AREA BELOW FOR TRAINING PURPOSES USING A DEMO ACCOUNT
A39: DATE | B39: TIME | C39: PAIR | D39: TRADE IMAGE | E39: TYPE | F39: RESULT | G39: GROWTH %
C91: TRADING RESULTS
D92: DO NOT EDIT THE FIELDS INSIDE THIS YELLOW BOX
C93: Live Trades
D94: Total Number of Winning Live Trades | E94: =COUNTIF(F2:F28,"WON") -> 8
D95: Total Number of Losing Live Trades | E95: =COUNTIF(F2:F28,"LOST") -> 8
D96: Total Number of Live Trades | E96: =E94+E95 -> 16
D97: Total Percentage Profit of Live Trades | E97: =SUM(G2:G28) -> 0.052
D98: Monthly Percentage Profit Target | E98: ='Data Calcs'!$S$2 -> 0.1 | F98: =IF(E97>=E98,"ACHIEVED","")
D99: Total Win Rate Live Trades | E99: =IFERROR((E94/E96),0) -> 0.5
C100: Demo Trades
D101: Total Number of Winning Demo Trades | E101: =COUNTIF(F40:F90,"WON") -> 0
D102: Total Number of Losing Demo Trades | E102: =COUNTIF(F40:F90,"LOST") -> 0
...

Sheet Aug24
A1: DATE | B1: TIME | C1: PAIR | D1: TRADE IMAGE | E1: TYPE | F1: RESULT | G1: GROWTH % | H1: Comments
A2: 45511 | B2: 8-9am | C2: EUR/USD | D2: https://www.tradingview.com/x/BP7OTN5z/ | E2: SELL | F2: LOST | G2: -0.01
A3: 45512 | B3: 8-9am | C3: EUR/USD | D3: https://www.tradingview.com/x/uXqHbFkn/ | E3: BUY | F3: WON | G3: 0.02
A4: 45513 | B4: 8-9am | C4: EUR/USD | D4: https://www.tradingview.com/x/TkXEPpc0/ | E4: SELL | F4: LOST | G4: -0.01
A5: 45513 | B5: 8-9am | C5: EUR/USD | D5: https://www.tradingview.com/x/TkXEPpc0/ | E5: SELL | F5: WON | G5: 0.015
A6: 45517 | B6: 8-9am | C6: EUR/USD | D6: https://www.tradingview.com/x/6lT4WXLr/ | E6: SELL | F6: WON | G6: 0.018 | H6: went to TP (being cautious)
A7: 45519 | B7: 3-4pm | C7: EUR/USD | D7: https://www.tradingview.com/x/xGVJCIfl/ | E7: BUY | F7: WON | G7: 0.02
A8: 45520 | B8: 8-9am | C8: EUR/USD | D8: https://www.tradingview.com/x/rCoOoMw0/ | E8: SELL | F8: LOST | G8: -0.01
A9: 45520 | B9: 8-9am | C9: EUR/USD | D9: https://www.tradingview.com/x/rCoOoMw0/ | E9: SELL | F9: WON | G9: 0.018 | H9: A bit too cautious price went into buy zone so took out early. went on to 2%
A10: 45524 | B10: 8-9am | C10: EUR/USD | D10: https://www.tradingview.com/x/CjZ2pQb0/ | E10: BUY | F10: LOST | G10: -0.01
A11: 45524 | B11: 8-9am | C11: EUR/USD | D11: https://www.tradingview.com/x/CjZ2pQb0/ | E11: SELL | F11: WON | G11: 0.018 | H11: A bit too cautious price went into buy zone so took out early. went on to 2%
A12: 45525 | B12: 8-9am | C12: EUR/USD | D12: https://www.tradingview.com/x/NqKF29DI/ | E12: SELL | F12: LOST | G12: -0.01
A13: 45525 | B13: 8-9am | C13: EUR/USD | D13: https://www.tradingview.com/x/NqKF29DI/ | E13: SELL | F13: WON | G13: 0.02
A14: 45527 | B14: 8-9am | C14: EUR/USD | D14: https://www.tradingview.com/x/A02knKD4/ | E14: SELL | F14: WON | G14: 0.02
A15: 45531 | B15: 8-9am | C15: EUR/USD | D15: https://www.tradingview.com/x/IjUylbBx/ | E15: BUY | F15: WON | G15: 0.01
C25: DO NOT EDIT THE FIELDS INSIDE THIS YELLOW BOX
D26: Total Number of Winning Trades | E26: =COUNTIF(F2:F24,"WON") -> 9
D27: Total Number of Losing Trades | E27: =COUNTIF(F2:F24,"LOST") -> 5
D28: Total Number of Live Trades | E28: =SUM(E26:E27) -> 14
D29: Total Percentage Profit of Current Month | E29: =SUM(G2:G24) -> 0.109
D30: Monthly Percentage Profit Target | E30: ='Data Calcs'!$S$2 -> 0.1 | F30: =IF(E29>=E30,"ACHIEVED","") -> ACHIEVED
A34: USE THE AREA BELOW FOR TRAINING PURPOSES USING A DEMO ACCOUNT
A35: DATE | B35: TIME | C35: PAIR | D35: TRADE IMAGE | E35: TYPE | F35: RESULT | G35: GROWTH %
A36: 45532 | B36: 8-9am | C36: EUR/USD | D36: https://www.tradingview.com/x/tVzUQ3je/ | E36: SELL | F36: LOST | G36: -0.01
C87: TRADING RESULTS
D88: DO NOT EDIT THE FIELDS INSIDE THIS YELLOW BOX
C89: Live Trades
D90: Total Number of Winning Live Trades | E90: =COUNTIF(F2:F24,"WON") -> 9
D91: Total Number of Losing Live Trades | E91: =COUNTIF(F2:F24,"LOST") -> 5
D92: Total Number of Live Trades | E92: =E90+E91 -> 14
D93: Total Percentage Profit of Live Trades | E93: =SUM(G2:G24) -> 0.109
D94: Monthly Percentage Profit Target | E94: ='Data Calcs'!$S$2 -> 0.1 | F94: =IF(E93>=E94,"ACHIEVED","") -> ACHIEVED
D95: Total Win Rate Live Trades | E95: =IFERROR((E90/E92),0) -> 0.64285714
C96: Demo Trades
D97: Total Number of Winning Demo Trades | E97: =COUNTIF(F36:F86,"WON") -> 0
D98: Total Number of Losing Demo Trades | E98: =COUNTIF(F36:F86,"LOST") -> 1
D99: Total Number of Demo Trades | E99: =E97+E98 -> 1
D100: Total Percentage Profit of Demo Trades | E100: =SUM(G35:G86) -> -0.01
D101: Total Win Rate Live Trades | E101: =IFERROR((E97/E99),0) -> 0
C102: Combined Live & Demo Trades
...

Sheet Sep24
A1: DATE | B1: TIME | C1: PAIR | D1: TRADE IMAGE | E1: TYPE | F1: RESULT | G1: GROWTH % | H1: Comments
A2: 45539 | B2: 8-9am | C2: EUR/USD | D2: https://www.tradingview.com/x/ArbZkqVh/ | E2: BUY | F2: WON | G2: 0.015
A3: 45540 | B3: 8-9am | C3: EUR/USD | D3: https://www.tradingview.com/x/7WGtFj2e/ | E3: SELL | F3: LOST | G3: 0 | H3: put SL to entry
A4: 45540 | B4: 8-9am | C4: EUR/USD | D4: https://www.tradingview.com/x/7WGtFj2e/ | E4: BUY | F4: LOST | G4: -0.01
A5: 45545 | B5: 3-4pm | C5: US100 | D5: https://www.tradingview.com/x/9w4shrf9/ | E5: SELL | F5: LOST | G5: -0.01
A6: 45546 | B6: 8-9am | C6: EUR/USD | D6: https://www.tradingview.com/x/xVNMPh52/ | E6: BUY | F6: LOST | G6: -0.01
A7: 45546 | B7: 8-9am | C7: EUR/USD | D7: https://www.tradingview.com/x/xVNMPh52/ | E7: BUY | F7: WON | G7: 0.01 | H7: Took profit at 1% because price in sell zone
A8: 45547 | B8: 3-4pm | C8: EUR/USD | D8: https://www.tradingview.com/x/1lFqi5xA/ | E8: SELL | F8: LOST | G8: -0.01
A9: 45547 | B9: 4-5pm | C9: US100 | D9: https://www.tradingview.com/x/Z5nBcRbY/ | E9: SELL | F9: WON | G9: 0.02
A10: 45548 | B10: 8-9am | C10: EUR/USD | D10: https://www.tradingview.com/x/yc97E5P8/ | E10: SELL | F10: LOST | G10: -0.01
A11: 45548 | B11: 7-8pm | C11: US100 | D11: https://www.tradingview.com/x/zgD2EDG3/ | E11: SELL | F11: WON | G11: 0.02
A12: 45552 | B12: 3-4pm | C12: EUR/USD | D12: https://www.tradingview.com/x/AL8D0bcR/ | E12: SELL | F12: LOST | G12: -0.01 | H12: 4 peices of non red flag news at 3pm (moved 5 pips) hit my sl
A13: 45552 | B13: 6-7pm | C13: US100 | D13: https://www.tradingview.com/x/EVQ5Upk4/ | E13: SELL | F13: WON | G13: 0.02
A14: 45553 | B14: 2-3pm | C14: US100 | D14: https://www.tradingview.com/x/e0FgCzru/ | E14: SELL | F14: WON | G14: 0.02
A15: 45554 | B15: 8-9am | C15: EUR/USD | D15: https://www.tradingview.com/x/1Hg2kdAT/ | E15: SELL | F15: LOST | G15: -0.01
A16: 45554 | B16: 2-3pm | C16: US100 | D16: https://www.tradingview.com/x/aC87UKuO/ | E16: BUY | F16: WON | G16: 0.015
A17: 45555 | B17: 8-9am | C17: EUR/USD | D17: https://www.tradingview.com/x/R4k945K1/ | E17: SELL | F17: LOST | G17: -0.01 | H17: Sl hit by a few 10ths of a pip then went on to hit TP
A18: 45559 | B18: 2-3pm | C18: US100 | D18: https://www.tradingview.com/x/67N2uZGw/ | E18: SELL | F18: WON | G18: 0.02
A19: 45560 | B19: 8-9am | C19: EUR/USD | D19: https://www.tradingview.com/x/ml2KAAGK/ | E19: SELL | G19: 0 | H19: put SL to break even (protect equity) the trade would have lost
A20: 45560 | B20: 2-3pm | C20: US100 | D20: https://www.tradingview.com/x/955Bz0SE/ | E20: BUY | F20: WON | G20: 0.015 | H20: Took profit early, price turned after and would have lost
A21: 45561 | B21: 8-9am | C21: EUR/USD | D21: https://www.tradingview.com/x/bOcUP1ld/ | E21: SELL | F21: WON | G21: 0.015 | H21: got out early because of red flag news
A22: 45562 | B22: 8-9am | C22: EUR/USD | D22: https://www.tradingview.com/x/yoOnrn8Y/ | E22: BUY | F22: LOST | G22: -0.01
A23: 45562 | B23: 9-10am | C23: EUR/USD | D23: https://www.tradingview.com/x/yoOnrn8Y/ | E23: BUY | F23: WON | G23: 0.02
C29: DO NOT EDIT THE FIELDS INSIDE THIS YELLOW BOX
D30: Total Number of Winning Trades | E30: =COUNTIF(F2:F28,"WON") -> 11
D31: Total Number of Losing Trades | E31: =COUNTIF(F2:F28,"LOST") -> 10
D32: Total Number of Live Trades | E32: =SUM(E30:E31) -> 21
D33: Total Percentage Profit of Current Month | E33: =SUM(G2:G28) -> 0.1
D34: Monthly Percentage Profit Target | E34: ='Data Calcs'!$S$2 -> 0.1 | F34: =IF(E33>=E34,"ACHIEVED","") -> ACHIEVED
A38: USE THE AREA BELOW FOR TRAINING PURPOSES USING A DEMO ACCOUNT
A39: DATE | B39: TIME | C39: PAIR | D39: TRADE IMAGE | E39: TYPE | F39: RESULT | G39: GROWTH %
C91: TRADING RESULTS
D92: DO NOT EDIT THE FIELDS INSIDE THIS YELLOW BOX
C93: Live Trades
D94: Total Number of Winning Live Trades | E94: =COUNTIF(F2:F28,"WON") -> 11
D95: Total Number of Losing Live Trades | E95: =COUNTIF(F2:F28,"LOST") -> 10
D96: Total Number of Live Trades | E96: =E94+E95 -> 21
D97: Total Percentage Profit of Live Trades | E97: =SUM(G2:G28) -> 0.1
D98: Monthly Percentage Profit Target | E98: ='Data Calcs'!$S$2 -> 0.1 | F98: =IF(E97>=E98,"ACHIEVED","") -> ACHIEVED
D99: Total Win Rate Live Trades | E99: =IFERROR((E94/E96),0) -> 0.52380952
...

Sheet Oct24
A1: DATE | B1: TIME | C1: PAIR | D1: TRADE IMAGE | E1: TYPE | F1: RESULT | G1: GROWTH % | H1: Comments
A2: 45567 | B2: 3-4pm | C2: EUR/USD | D2: https://www.tradingview.com/x/awt8Z152/ | E2: BUY | F2: LOST | G2: -0.01
A3: 45567 | B3: 3-4pm | C3: US100 | D3: https://www.tradingview.com/x/dXt40l1r/ | E3: BUY | G3: 0 | H3: put sl to breakeven too early, price took entry out for break even and then went onto hit tp
A4: 45573 | B4: 2-3pm | C4: US100 | D4: https://www.tradingview.com/x/V5calZc8/ | E4: BUY | F4: WON | G4: 0.02
A5: 45574 | B5: 8-9am | C5: EUR/USD | D5: https://www.tradingview.com/x/59PtNawb/ | E5: BUY | F5: WON | G5: 0.015 | H5: Trade would have lost if I had not got out early
A6: 45575 | B6: 8-9am | C6: EUR/USD | D6: https://www.tradingview.com/x/vfLGeuuB/ | E6: BUY | F6: WON | G6: 0.01 | H6: price would of hit sl
A7: 45576 | B7: 8-9am | C7: EUR/USD | D7: https://www.tradingview.com/x/SxTyOHjf/ | E7: SELL | F7: LOST | G7: -0.01
A8: 45576 | B8: 10-11am | C8: EUR/USD | D8: https://www.tradingview.com/x/6OPMSupv/ | E8: SELL | F8: WON | G8: 0.02
A9: 45580 | B9: 2-3pm | C9: EUR/USD | D9: https://www.tradingview.com/x/syQTZ1x6/ | E9: BUY | F9: LOST | G9: -0.01
A10: 45580 | B10: 3-4pm | C10: EUR/USD | D10: https://www.tradingview.com/x/syQTZ1x6/ | E10: SELL | F10: WON | G10: 0.015 | H10: took out on EMA 462 but would have won 2%
A11: 45581 | B11: 8-9am | C11: EUR/USD | D11: https://www.tradingview.com/x/XdxJJhyw/ | E11: BUY | F11: LOST | G11: -0.01
A12: 45581 | B12: 9-10am | C12: EUR/USD | D12: https://www.tradingview.com/x/jgdhUdJ9/ | E12: BUY | F12: WON | G12: 0.02
A13: 45582 | B13: 8-9am | C13: EUR/USD | D13: https://www.tradingview.com/x/QFRBYZ8j/ | E13: SELL | F13: LOST | G13: -0.01
A14: 45582 | B14: 3-4pm | C14: US100 | D14: https://www.tradingview.com/x/RMLVvKsY/ | E14: BUY | F14: LOST | G14: -0.01
A15: 45583 | B15: 8-9am | C15: EUR/USD | D15: https://www.tradingview.com/x/Tl7L2VA4/ | E15: SELL | F15: WON | G15: 0.01
A16: 45587 | B16: 8-9am | C16: EUR/USD | D16: https://www.tradingview.com/x/FwYYb9nL/ | E16: BUY | F16: WON | G16: 0.02
A17: 45588 | B17: 8-9am | C17: EUR/USD | D17: https://www.tradingview.com/x/uzFL0zfU/ | E17: BUY | F17: LOST | G17: -0.01
A18: 45588 | B18: 9-10am | C18: EUR/USD | D18: https://www.tradingview.com/x/RD817IBR/ | E18: BUY | F18: WON | G18: 0.02
A19: 45590 | B19: 8-9am | C19: EUR/USD | D19: https://www.tradingview.com/x/kSezqact/ | E19: BUY | F19: WON | G19: 0.02
C29: DO NOT EDIT THE FIELDS INSIDE THIS YELLOW BOX
D30: Total Number of Winning Trades | E30: =COUNTIF(F2:F28,"WON") -> 10
D31: Total Number of Losing Trades | E31: =COUNTIF(F2:F28,"LOST") -> 7
D32: Total Number of Live Trades | E32: =SUM(E30:E31) -> 17
D33: Total Percentage Profit of Current Month | E33: =SUM(G2:G28) -> 0.1
D34: Monthly Percentage Profit Target | E34: ='Data Calcs'!$S$2 -> 0.1 | F34: =IF(E33>=E34,"ACHIEVED","") -> ACHIEVED
A38: USE THE AREA BELOW FOR TRAINING PURPOSES USING A DEMO ACCOUNT
A39: DATE | B39: TIME | C39: PAIR | D39: TRADE IMAGE | E39: TYPE | F39: RESULT | G39: GROWTH %
A40: 45595 | B40: 1-2pm | C40: US100 | D40: https://www.tradingview.com/x/2lfwwuXk/ | E40: BUY | F40: WON | G40: 0.02
A41: 45596 | B41: 8-9am | C41: EUR/USD | D41: https://www.tradingview.com/x/vCtNyB28/ | E41: SELL | G41: 0 | H41: Break even, trade would have lost
A42: 45596 | B42: 8-9am | C42: EUR/USD | D42: https://www.tradingview.com/x/vCtNyB28/ | E42: BUY | F42: LOST | G42: -0.01
C91: TRADING RESULTS
D92: DO NOT EDIT THE FIELDS INSIDE THIS YELLOW BOX
C93: Live Trades
D94: Total Number of Winning Live Trades | E94: =COUNTIF(F2:F28,"WON") -> 10
D95: Total Number of Losing Live Trades | E95: =COUNTIF(F2:F28,"LOST") -> 7
D96: Total Number of Live Trades | E96: =E94+E95 -> 17
D97: Total Percentage Profit of Live Trades | E97: =SUM(G2:G28) -> 0.1
D98: Monthly Percentage Profit Target | E98: ='Data Calcs'!$S$2 -> 0.1 | F98: =IF(E97>=E98,"ACHIEVED","") -> ACHIEVED
D99: Total Win Rate Live Trades | E99: =IFERROR((E94/E96),0) -> 0.58823529
C100: Demo Trades
...

Sheet Nov24
A1: DATE | B1: TIME | C1: PAIR | D1: TRADE IMAGE | E1: TYPE | F1: RESULT | G1: GROWTH % | H1: Comments
A2: 45601 | B2: 8-9am | C2: EUR/USD | D2: https://www.tradingview.com/x/9O9UQmgv/ | E2: SELL | F2: LOST | G2: -0.01
A3: 45601 | B3: 8-9am | C3: EUR/USD | D3: https://www.tradingview.com/x/9O9UQmgv/ | E3: SELL | F3: LOST | G3: -0.01
A4: 45602 | B4: 3-4pm | C4: US100 | D4: https://www.tradingview.com/x/4gmAQbNq/ | E4: SELL | F4: LOST | G4: -0.01
A5: 45602 | B5: 3-4pm | C5: US100 | D5: https://www.tradingview.com/x/4gmAQbNq/ | E5: SELL | G5: 0
A6: 45604 | B6: 8-9am | C6: EUR/USD | D6: https://www.tradingview.com/x/Ve0dgBTu/ | E6: BUY | F6: LOST | G6: -0.01
A7: 45608 | B7: 8-9am | C7: EUR/USD | D7: https://www.tradingview.com/x/rbsmmRVC/ | E7: BUY | F7: LOST | G7: -0.01
A8: 45608 | B8: 9-10am | C8: EUR/USD | D8: https://www.tradingview.com/x/rbsmmRVC/ | E8: SELL | F8: WON | G8: 0.018
A9: 45609 | B9: 8-9am | C9: EUR/USD | D9: https://www.tradingview.com/x/deKk7LS5/ | E9: BUY | F9: LOST | G9: -0.01
A10: 45610 | B10: 3-4pm | C10: US100 | D10: https://www.tradingview.com/x/5gngho1z/ | E10: BUY | G10: 0 | H10: breakeven
A11: 45610 | B11: 3-4pm | C11: EUR/USD | D11: https://www.tradingview.com/x/OCLMFnpj/ | E11: SELL | F11: LOST | G11: -0.01
A12: 45611 | B12: 9-10am | C12: EUR/USD | D12: https://www.tradingview.com/x/v0axB3SO/ | E12: SELL | F12: WON | G12: 0.02
A13: 45615 | B13: 9-10am | C13: EUR/USD | D13: https://www.tradingview.com/x/Ac91vlZd/ | E13: BUY | F13: WON | G13: 0.02
A14: 45615 | B14: 8-9am | C14: EUR/USD | D14: https://www.tradingview.com/x/VvbTmd5R/ | E14: SELL | F14: LOST | G14: -0.01 | H14: Anticipated a red trend on our indicator, didnt happen, should be NO trade
A15: 45616 | B15: 8-9am | C15: EUR/USD | D15: https://www.tradingview.com/x/nLnF4Xn1/ | E15: SELL | G15: 0 | H15: St L to entry and breakeven BUT would have won if not moved SL
A16: 45616 | B16: 9-10am | C16: EUR/USD | D16: https://www.tradingview.com/x/8m86BZlT/ | E16: SELL | F16: WON | G16: 0.02
A17: 45617 | B17: 8-9am | C17: EUR/USD | D17: https://www.tradingview.com/x/NaWg8zqJ/ | E17: BUY | F17: WON | G17: 0.018
A18: 45621 | B18: 3-4pm | C18: EUR/USD | D18: https://www.tradingview.com/x/2PRkJeST/ | E18: BUY | F18: WON | G18: 0.02
A19: 45623 | B19: 8-9am | C19: EUR/USD | D19: https://www.tradingview.com/x/sd0fdkTD/ | E19: SELL | F19: WON | G19: 0.004
A20: 45625 | B20: 8-9am | C20: EUR/USD | D20: https://www.tradingview.com/x/HhaVlbb2/ | E20: BUY | F20: LOST | G20: -0.01
C29: DO NOT EDIT THE FIELDS INSIDE THIS YELLOW BOX
D30: Total Number of Winning Trades | E30: =COUNTIF(F2:F28,"WON") -> 7
D31: Total Number of Losing Trades | E31: =COUNTIF(F2:F28,"LOST") -> 9
D32: Total Number of Live Trades | E32: =SUM(E30:E31) -> 16
D33: Total Percentage Profit of Current Month | E33: =SUM(G2:G28) -> 0.03
D34: Monthly Percentage Profit Target | E34: ='Data Calcs'!$S$2 -> 0.1 | F34: =IF(E33>=E34,"ACHIEVED","")
A38: USE THE AREA BELOW FOR TRAINING PURPOSES USING A DEMO ACCOUNT
A39: DATE | B39: TIME | C39: PAIR | D39: TRADE IMAGE | E39: TYPE | F39: RESULT | G39: GROWTH %
C91: TRADING RESULTS
D92: DO NOT EDIT THE FIELDS INSIDE THIS YELLOW BOX
C93: Live Trades
D94: Total Number of Winning Live Trades | E94: =COUNTIF(F2:F28,"WON") -> 7
D95: Total Number of Losing Live Trades | E95: =COUNTIF(F2:F28,"LOST") -> 9
D96: Total Number of Live Trades | E96: =E94+E95 -> 16
D97: Total Percentage Profit of Live Trades | E97: =SUM(G2:G28) -> 0.03
D98: Monthly Percentage Profit Target | E98: ='Data Calcs'!$S$2 -> 0.1 | F98: =IF(E97>=E98,"ACHIEVED","")
D99: Total Win Rate Live Trades | E99: =IFERROR((E94/E96),0) -> 0.4375
C100: Demo Trades
D101: Total Number of Winning Demo Trades | E101: =COUNTIF(F40:F90,"WON") -> 0
D102: Total Number of Losing Demo Trades | E102: =COUNTIF(F40:F90,"LOST") -> 0
...

Sheet Dec24
A1: DATE | B1: TIME | C1: PAIR | D1: TRADE IMAGE | E1: TYPE | F1: RESULT | G1: GROWTH % | H1: Comments
A2: 45628 | B2: 8-9am | C2: EUR/USD | D2: https://www.tradingview.com/x/EILMLwpt/ | E2: BUY | F2: LOST | G2: -0.01
A3: 45629 | B3: 8-9am | C3: EUR/USD | D3: https://www.tradingview.com/x/3IMV0pUC/ | E3: SELL | F3: LOST | G3: -0.01
A4: 45629 | B4: 9-10am | C4: EUR/USD | D4: https://www.tradingview.com/x/Cgsl5pXi/ | E4: SELL | F4: WON | G4: 0.02
A5: 45630 | B5: 9-10am | C5: EUR/USD | D5: https://www.tradingview.com/x/7POCxHZe/ | E5: BUY | F5: WON | G5: 0.02
A6: 45631 | B6: 8-9am | C6: EUR/USD | D6: https://www.tradingview.com/x/BGsoaxVp/ | E6: BUY | F6: WON | G6: 0.016
A7: 45632 | B7: 8-9am | C7: EUR/USD | D7: https://www.tradingview.com/x/IOSBqeEL/ | E7: SELL | F7: WON | G7: 0.02
A8: 45635 | B8: 3-4pm | C8: US100 | D8: https://www.tradingview.com/x/cS4cvyyk/ | E8: SELL | F8: WON | G8: 0.02
A9: 45636 | B9: 8-9am | C9: EUR/USD | D9: https://www.tradingview.com/x/eNZ2Rz3U/ | E9: BUY | F9: LOST | G9: -0.01
A10: 45636 | B10: 9-10am | C10: EUR/USD | D10: https://www.tradingview.com/x/eNZ2Rz3U/ | E10: SELL | F10: WON | G10: 0.01 | H10: took partial profit but went to 2%
A11: 45637 | B11: 8-9am | C11: EUR/USD | D11: https://www.tradingview.com/x/LluF0MOk/ | E11: BUY | F11: LOST | G11: -0.01
A12: 45637 | B12: 8-9am | C12: EUR/USD | D12: https://www.tradingview.com/x/LluF0MOk/ | E12: BUY | F12: LOST | G12: -0.01
A13: 45638 | B13: 9-10am | C13: EUR/USD | D13: https://www.tradingview.com/x/eo6NndKx/ | E13: BUY | F13: WON | G13: 0.004
A14: 45639 | B14: 8-9am | C14: EUR/USD | D14: https://www.tradingview.com/x/Gh98O8Z9/ | E14: SELL | F14: LOST | G14: -0.01 | H14: manual error, anticipated trend colour change, didnt happen
A15: 45639 | B15: 3-4pm | C15: US100 | D15: https://www.tradingview.com/x/nkvguoze/ | E15: SELL | F15: WON | G15: 0.02
A16: 45643 | B16: 2-3pm | C16: US100 | D16: https://www.tradingview.com/x/PZM3Pdzu/ | E16: SELL | F16: WON | G16: 0.02
A17: 45644 | B17: 2-3pm | C17: US100 | D17: https://www.tradingview.com/x/HZJDTj14/ | E17: BUY | F17: WON | G17: 0.01
C29: DO NOT EDIT THE FIELDS INSIDE THIS YELLOW BOX
D30: Total Number of Winning Trades | E30: =COUNTIF(F2:F28,"WON") -> 10
D31: Total Number of Losing Trades | E31: =COUNTIF(F2:F28,"LOST") -> 6
D32: Total Number of Live Trades | E32: =SUM(E30:E31) -> 16
D33: Total Percentage Profit of Current Month | E33: =SUM(G2:G28) -> 0.1
D34: Monthly Percentage Profit Target | E34: ='Data Calcs'!$S$2 -> 0.1 | F34: =IF(E33>=E34,"ACHIEVED","") -> ACHIEVED
A38: USE THE AREA BELOW FOR TRAINING PURPOSES USING A DEMO ACCOUNT
A39: DATE | B39: TIME | C39: PAIR | D39: TRADE IMAGE | E39: TYPE | F39: RESULT | G39: GROWTH %
A40: 45645 | B40: 2-3pm | C40: US100 | D40: https://www.tradingview.com/x/cMaJyu73/ | E40: SELL | F40: WON | G40: 0.02
A41: 45646 | B41: 8-9am | C41: EUR/USD | D41: https://www.tradingview.com/x/pUn6SAUr/ | E41: SELL | F41: WON | G41: 0.02
C90: TRADING RESULTS
D91: DO NOT EDIT THE FIELDS INSIDE THIS YELLOW BOX
C92: Live Trades
D93: Total Number of Winning Live Trades | E93: =COUNTIF(F2:F28,"WON") -> 10
D94: Total Number of Losing Live Trades | E94: =COUNTIF(F2:F28,"LOST") -> 6
D95: Total Number of Live Trades | E95: =E93+E94 -> 16
D96: Total Percentage Profit of Live Trades | E96: =SUM(G2:G28) -> 0.1
D97: Monthly Percentage Profit Target | E97: ='Data Calcs'!$S$2 -> 0.1 | F97: =IF(E96>=E97,"ACHIEVED","") -> ACHIEVED
D98: Total Win Rate Live Trades | E98: =IFERROR((E93/E95),0) -> 0.625
C99: Demo Trades
D100: Total Number of Winning Demo Trades | E100: =COUNTIF(F40:F89,"WON") -> 2
D101: Total Number of Losing Demo Trades | E101: =COUNTIF(F40:F89,"LOST") -> 0
D102: Total Number of Demo Trades | E102: =E100+E101 -> 2
...

Sheet Jan25
A1: DATE | B1: TIME | C1: PAIR | D1: TRADE IMAGE | E1: TYPE | F1: RESULT | G1: GROWTH % | H1: Comments
A2: 45664 | B2: 1-2pm | C2: EUR/USD | D2: https://www.tradingview.com/x/Bxdpqcst/ | E2: BUY | F2: WON | G2: 0.01 | H2: Trade would of lost if not managed SL
A3: 45665 | B3: 8-9am | C3: EUR/USD | D3: https://www.tradingview.com/x/LvorEDgL/ | E3: BUY | F3: LOST | G3: -0.01
A4: 45665 | B4: 12-1pm | C4: EUR/USD | D4: https://www.tradingview.com/x/tA6ZuR2G/ | E4: SELL | F4: WON | G4: 0.01 | H4: Trade would of lost if not managed SL
A5: 45666 | B5: 8-9am | C5: EUR/USD | D5: https://www.tradingview.com/x/E2vGzfai/ | E5: BUY | F5: WON | G5: 0.004 | H5: would have gone to 2%
A6: 45667 | B6: 8-9am | C6: EUR/USD | D6: https://www.tradingview.com/x/309aJ3GM/ | E6: SELL | F6: LOST | G6: -0.01
A7: 45667 | B7: 3-4pm | C7: US100 | D7: https://www.tradingview.com/x/YHn8MDtv/ | E7: BUY | F7: WON | G7: 0.02
A8: 45671 | B8: 8-9am | C8: EUR/USD | D8: https://www.tradingview.com/x/lWrjrYAb/ | E8: BUY | F8: LOST | G8: -0.01
A9: 45671 | B9: 2-3pm | C9: US100 | D9: https://www.tradingview.com/x/wQuCXkOk/ | E9: BUY | F9: WON | G9: 0.02
A10: 45672 | B10: 8-9am | C10: EUR/USD | D10: https://www.tradingview.com/x/JAujcNsC/ | E10: SELL | F10: WON | G10: 0.02
A11: 45673 | B11: 8-9am | C11: EUR/USD | D11: https://www.tradingview.com/x/w8nCcWPE/ | E11: SELL | F11: LOST | G11: -0.01
A12: 45673 | B12: 9-10am | C12: EUR/USD | D12: https://www.tradingview.com/x/8bZKrGcB/ | E12: BUY | F12: WON | G12: 0.02
A13: 45679 | B13: 4-5pm | C13: US100 | D13: https://www.tradingview.com/x/hkkbFyQR/ | E13: BUY | F13: WON | G13: 0.01 | H13: dont push it take 1% but it did 2% in the end
A14: 45680 | B14: 8-9am | C14: EUR/USD | D14: https://www.tradingview.com/x/i9MCuqrC/ | E14: BUY | F14: LOST | G14: -0.01
A15: 45680 | B15: 8-9am | C15: EUR/USD | D15: https://www.tradingview.com/x/i9MCuqrC/ | E15: BUY | F15: LOST | G15: -0.01
A16: 45681 | B16: 9-10am | C16: EUR/USD | D16: https://www.tradingview.com/x/v971RD9Q/ | E16: SELL | F16: WON | G16: 0.02
A17: 45685 | B17: 8-9am | C17: EUR/USD | D17: https://www.tradingview.com/x/AXmDwYPd/ | E17: BUY | F17: LOST | G17: -0.01
A18: 45685 | B18: 9-10am | C18: EUR/USD | D18: https://www.tradingview.com/x/dHyOGV1j/ | E18: BUY | F18: WON | G18: 0.01 | H18: in the trade a long time so decided to take 1% but 2% was acheived
A19: 45686 | B19: 8-9am | C19: EUR/USD | D19: https://www.tradingview.com/x/8qqOXQGS/ | E19: BUY | F19: WON | G19: 0.005
A20: 45687 | B20: 8-9am | C20: EUR/USD | D20: https://www.tradingview.com/x/YpUn4mom/ | E20: SELL | F20: LOST | G20: -0.01
A21: 45687 | B21: 4-5pm | C21: US100 | D21: https://www.tradingview.com/x/3EP3bpeK/ | E21: BUY | F21: WON | G21: 0.01
A22: 45688 | B22: 9-10am | C22: EUR/USD | D22: https://www.tradingview.com/x/L4Q8ydOT/ | E22: BUY | F22: WON | G22: 0.02
C29: DO NOT EDIT THE FIELDS INSIDE THIS YELLOW BOX
D30: Total Number of Winning Trades | E30: =COUNTIF(F2:F28,"WON") -> 13
D31: Total Number of Losing Trades | E31: =COUNTIF(F2:F28,"LOST") -> 8
D32: Total Number of Live Trades | E32: =SUM(E30:E31) -> 21
D33: Total Percentage Profit of Current Month | E33: =SUM(G2:G28) -> 0.099
D34: Monthly Percentage Profit Target | E34: ='Data Calcs'!$S$2 -> 0.1 | F34: =IF(E33>=E34,"ACHIEVED","")
A38: USE THE AREA BELOW FOR TRAINING PURPOSES USING A DEMO ACCOUNT
A39: DATE | B39: TIME | C39: PAIR | D39: TRADE IMAGE | E39: TYPE | F39: RESULT | G39: GROWTH %
C90: TRADING RESULTS
D91: DO NOT EDIT THE FIELDS INSIDE THIS YELLOW BOX
C92: Live Trades
D93: Total Number of Winning Live Trades | E93: =E30 -> 13
D94: Total Number of Losing Live Trades | E94: =E31 -> 8
D95: Total Number of Live Trades | E95: =E32 -> 21
D96: Total Percentage Profit of Live Trades | E96: =E33 -> 0.099
D97: Monthly Percentage Profit Target | E97: ='Data Calcs'!$S$2 -> 0.1 | F97: =IF(E96>=E97,"ACHIEVED","")
D98: Total Win Rate Live Trades | E98: =IFERROR((E93/E95),0) -> 0.61904762
C99: Demo Trades
...

Sheet Feb25
A1: DATE | B1: TIME | C1: PAIR | D1: TRADE IMAGE | E1: TYPE | F1: RESULT | G1: GROWTH % | H1: Comments
A2: 45693 | B2: 10-11am | C2: EUR/USD | D2: https://www.tradingview.com/x/xxpJgmxJ/ | E2: BUY | F2: WON | G2: 0.01
A3: 45694 | B3: 8-9am | C3: EUR/USD | D3: https://www.tradingview.com/x/ww7c1KWO/ | E3: BUY | F3: LOST | G3: -0.01
A4: 45694 | B4: 4-5pm | C4: EUR/USD | D4: https://www.tradingview.com/x/nzazKSdq/ | E4: BUY | F4: WON | G4: 0.01
A5: 45695 | B5: 9-10am | C5: EUR/USD | D5: https://www.tradingview.com/x/LjHySdQY/ | E5: SELL | G5: 0 | H5: BreakEven
A6: 45695 | B6: 9-10am | C6: EUR/USD | D6: https://www.tradingview.com/x/8YoAyKqV/ | E6: SELL | F6: WON | G6: 0.016 | H6: price stalled on support line hence 1;6%
A7: 45699 | B7: 2-3pm | C7: US100 | D7: https://www.tradingview.com/x/td2Z99nP/ | E7: BUY | F7: WON | G7: 0.02
A8: 45700 | B8: 8-9am | C8: EUR/USD | D8: https://www.tradingview.com/x/v3IxgXdz/ | E8: SELL | F8: LOST | G8: -0.01
A9: 45700 | B9: 3-4pm | C9: US100 | D9: https://www.tradingview.com/x/UroRE9so/ | E9: SELL | F9: WON | G9: 0.015 | H9: went to 2%
A10: 45701 | B10: 9-10am | C10: EUR/USD | D10: https://www.tradingview.com/x/5faPHgDW/ | E10: BUY | F10: WON | G10: 0.019 | H10: went to 2%
A11: 45702 | B11: 8-9am | C11: EUR/USD | D11: https://www.tradingview.com/x/yqCAYZ0J/ | E11: SELL | F11: LOST | G11: -0.01
A12: 45702 | B12: 12-1pm | C12: EUR/USD | D12: https://www.tradingview.com/x/tNJmymNw/ | E12: SELL | F12: WON | G12: 0.02
A13: 45706 | B13: 8-9am | C13: EUR/USD | D13: https://www.tradingview.com/x/CA6A26WR/ | E13: SELL | F13: LOST | G13: -0.01
A14: 45706 | B14: 8-9am | C14: EUR/USD | D14: https://www.tradingview.com/x/yGYIIt0r/ | E14: SELL | F14: WON | G14: 0.02
A15: 45707 | B15: 8-9am | C15: EUR/USD | D15: https://www.tradingview.com/x/1SVlRpGg/ | E15: BUY | F15: LOST | G15: -0.01
A16: 45707 | B16: 2-3pm | C16: US100 | D16: https://www.tradingview.com/x/ylkY3amU/ | E16: SELL | F16: WON | G16: 0.02
C29: DO NOT EDIT THE FIELDS INSIDE THIS YELLOW BOX
D30: Total Number of Winning Trades | E30: =COUNTIF(F2:F28,"WON") -> 9
D31: Total Number of Losing Trades | E31: =COUNTIF(F2:F28,"LOST") -> 5
D32: Total Number of Live Trades | E32: =SUM(E30:E31) -> 14
D33: Total Percentage Profit of Current Month | E33: =SUM(G2:G28) -> 0.1
D34: Monthly Percentage Profit Target | E34: ='Data Calcs'!$S$2 -> 0.1 | F34: =IF(E33>=E34,"ACHIEVED","") -> ACHIEVED
A38: USE THE AREA BELOW FOR TRAINING PURPOSES USING A DEMO ACCOUNT
A39: DATE | B39: TIME | C39: PAIR | D39: TRADE IMAGE | E39: TYPE | F39: RESULT | G39: GROWTH %
A40: 45708 | B40: 8-9am | C40: EUR/USD | D40: https://www.tradingview.com/x/8Nq7LBJx/ | E40: SELL | F40: WON | G40: 0.02
A41: 45713 | B41: 8-9am | C41: EUR/USD | D41: https://www.tradingview.com/x/lP8EIA2G/ | E41: BUY | F41: LOST | G41: -0.01
A42: 45713 | B42: 3-4pm | C42: EUR/USD | D42: https://www.tradingview.com/x/cWITgIWF/ | E42: SELL | F42: WON | G42: 0.02
A43: 45714 | B43: 8-9am | C43: EUR/USD | D43: https://www.tradingview.com/x/LIiDpocp/ | E43: SELL | F43: WON | G43: 0.018
A44: 45715 | B44: 8-9am | C44: EUR/USD | D44: https://www.tradingview.com/x/gOKLy4LF/ | E44: SELL | F44: LOST | G44: -0.01
A45: 45715 | B45: 2-3pm | C45: US100 | D45: https://www.tradingview.com/x/h36gCGS4/ | E45: SELL | F45: WON | G45: 0.02
C90: TRADING RESULTS
D91: DO NOT EDIT THE FIELDS INSIDE THIS YELLOW BOX
C92: Live Trades
D93: Total Number of Winning Live Trades | E93: =E30 -> 9
D94: Total Number of Losing Live Trades | E94: =E31 -> 5
D95: Total Number of Live Trades | E95: =E32 -> 14
D96: Total Percentage Profit of Live Trades | E96: =E33 -> 0.1
D97: Monthly Percentage Profit Target | E97: ='Data Calcs'!$S$2 -> 0.1 | F97: =IF(E96>=E97,"ACHIEVED","") -> ACHIEVED
D98: Total Win Rate Live Trades | E98: =IFERROR((E93/E95),0) -> 0.64285714
C99: Demo Trades
...

Sheet Mar25
A1: DATE | B1: TIME | C1: PAIR | D1: TRADE IMAGE | E1: TYPE | F1: RESULT | G1: GROWTH % | H1: Comments
A2: 45720 | B2: 8-9am | C2: EUR/USD | D2: https://www.tradingview.com/x/I8T0H4LY/ | E2: SELL | F2: LOST | G2: -0.01
A3: 45720 | B3: 9-10am | C3: EUR/USD | D3: https://www.tradingview.com/x/2EUQP7Su/ | E3: SELL | F3: WON | G3: 0.02
A4: 45721 | B4: 9-10am | D4: https://www.tradingview.com/x/QRUHP9dH/ | E4: SELL | F4: WON | G4: 0 | H4: Trade won but put stop loss to entry to protect equity
A5: 45723 | B5: 8-9am | C5: EUR/USD | D5: https://www.tradingview.com/x/fNYwjck2/ | E5: SELL | F5: LOST | G5: -0.01
A6: 45723 | B6: 8-9am | C6: EUR/USD | D6: https://www.tradingview.com/x/d0Ska7VG/ | E6: SELL | F6: LOST | G6: -0.01
A7: 45728 | B7: 8-9am | C7: EUR/USD | D7: https://www.tradingview.com/x/hX7cxirL/ | E7: SELL | F7: LOST | G7: -0.01
A8: 45728 | B8: 1-2pm | C8: US100 | D8: https://www.tradingview.com/x/3Z4OYbcu/ | E8: BUY | F8: WON | G8: 0.02
A9: 45729 | B9: 8-9am | C9: EUR/USD | D9: https://www.tradingview.com/x/Mgs6dkCo/ | E9: BUY | F9: LOST | G9: -0.01
A10: 45729 | B10: 1-2pm | C10: US100 | D10: https://www.tradingview.com/x/WpnDuYRD/ | E10: SELL | F10: WON | G10: 0.02
A11: 45730 | B11: 8-9am | C11: EUR/USD | D11: https://www.tradingview.com/x/098jEcuE/ | E11: SELL | F11: LOST | G11: -0.01
A12: 45734 | B12: 9-10am | C12: EUR/USD | D12: https://www.tradingview.com/x/pC6gqsRp/ | E12: SELL | F12: WON | G12: 0.02
A13: 45736 | B13: 9-10am | C13: EUR/USD | D13: https://www.tradingview.com/x/NkvwB9mh/ | E13: BUY | F13: LOST | G13: -0.01
A14: 45736 | B14: 1-2pm | C14: US100 | D14: https://www.tradingview.com/x/NJWmP266/ | E14: BUY | F14: WON | G14: 0.02
A15: 45741 | B15: 8-9am | C15: EUR/USD | D15: https://www.tradingview.com/x/04SYkTBJ/ | E15: BUY | F15: WON | G15: 0.02 | H15: Steve Trading for David
A16: 45743 | B16: 8-9am | C16: EUR/USD | D16: https://www.tradingview.com/x/CPPnMas3/ | E16: BUY | F16: LOST | G16: -0.01 | H16: Steve Trading for David - Reached 1.9% but turned around
A17: 45744 | B17: 8-9am | C17: EUR/USD | D17: https://www.tradingview.com/x/sRiCOHoe/ | E17: BUY | F17: LOST | G17: -0.01 | H17: Steve Trading for David
A18: 45744 | B18: 10-11am | C18: EUR/USD | D18: https://www.tradingview.com/x/sRiCOHoe/ | E18: SELL | F18: WON | G18: 0.02 | H18: Steve Trading for David
C29: DO NOT EDIT THE FIELDS INSIDE THIS YELLOW BOX
D30: Total Number of Winning Trades | E30: =COUNTIF(F2:F28,"WON") -> 8
D31: Total Number of Losing Trades | E31: =COUNTIF(F2:F28,"LOST") -> 9
D32: Total Number of Live Trades | E32: =SUM(E30:E31) -> 17
D33: Total Percentage Profit of Current Month | E33: =SUM(G2:G28) -> 0.05
D34: Monthly Percentage Profit Target | E34: ='Data Calcs'!$S$2 -> 0.1 | F34: =IF(E33>=E34,"ACHIEVED","")
A38: USE THE AREA BELOW FOR TRAINING PURPOSES USING A DEMO ACCOUNT
A39: DATE | B39: TIME | C39: PAIR | D39: TRADE IMAGE | E39: TYPE | F39: RESULT | G39: GROWTH %
C90: TRADING RESULTS
D91: DO NOT EDIT THE FIELDS INSIDE THIS YELLOW BOX
C92: Live Trades
D93: Total Number of Winning Live Trades | E93: =E30 -> 8
D94: Total Number of Losing Live Trades | E94: =E31 -> 9
D95: Total Number of Live Trades | E95: =E32 -> 17
D96: Total Percentage Profit of Live Trades | E96: =E33 -> 0.05
D97: Monthly Percentage Profit Target | E97: ='Data Calcs'!$S$2 -> 0.1 | F97: =IF(E96>=E97,"ACHIEVED","")
D98: Total Win Rate Live Trades | E98: =IFERROR((E93/E95),0) -> 0.47058824
C99: Demo Trades
D100: Total Number of Winning Demo Trades | E100: =COUNTIF(F40:F89,"WON") -> 0
D101: Total Number of Losing Demo Trades | E101: =COUNTIF(F40:F89,"LOST") -> 0
D102: Total Number of Demo Trades | E102: =E100+E101 -> 0
D103: Total Percentage Profit of Demo Trades | E103: =SUM(G39:G89) -> 0
...

Sheet Apr25
A1: DATE | B1: TIME | C1: PAIR | D1: TRADE IMAGE | E1: TYPE | F1: RESULT | G1: GROWTH % | H1: Comments | I1: Trader
A2: 45750 | B2: 2-3pm | C2: US100 | D2: https://www.tradingview.com/x/c7qeiiE3/ | E2: BUY | F2: WON | G2: 0.02 | H2: After EUR/USD turmoil in the morning session US100 was a clear setup | I2: Steve
A3: 45751 | B3: 10-11am | C3: EUR/USD | D3: https://www.tradingview.com/x/jIKZwBLe/ | E3: BUY | F3: LOST | G3: -0.01 | I3: Steve
A4: 45751 | B4: 11-12am | C4: EUR/USD | D4: https://www.tradingview.com/x/jIKZwBLe/ | E4: BUY | F4: WON | G4: 0.02 | I4: Steve
A5: 45754 | B5: 8-9am | C5: EUR/USD | D5: https://www.tradingview.com/x/VLJmSG90/ | E5: SELL | F5: LOST | G5: -0.01 | I5: Steve
A6: 45754 | B6: 12-1pm | C6: EUR/USD | D6: https://www.tradingview.com/x/iN6f0jBC/ | E6: BUY | F6: WON | G6: 0.02 | I6: Steve
A7: 45755 | B7: 8-9am | C7: EUR/USD | D7: https://www.tradingview.com/x/yXvlB5DQ/ | E7: BUY | F7: LOST | G7: -0.01 | H7: No second trade opportunity | I7: Steve
A8: 45762 | B8: 8-9am | C8: EUR/USD | D8: https://www.tradingview.com/x/cSHupD2l/ | E8: BUY | F8: WON | G8: 0 | H8: Moved SL to Break Even - Trade would have lost | I8: Steve
A9: 45762 | B9: 1-2pm | C9: EUR/USD | D9: https://www.tradingview.com/x/tDHLrqI1/ | E9: BUY | F9: WON | G9: 0.008 | H9: Moved SL slowly up to lock in profits settled for 0.8% would have been 2% | I9: Steve
A10: 45763 | B10: 4-5pm | C10: EUR/USD | D10: https://www.tradingview.com/x/NhReCHru/ | E10: BUY | F10: WON | G10: 0.0128 | H10: Moved SL slowly up to lock in profits.Would have reached 2% | I10: Steve
A11: 45764 | B11: 8-9am | C11: EUR/USD | D11: https://www.tradingview.com/x/GeLcSvKl/ | E11: SELL | F11: LOST | G11: -0.01 | I11: Steve
A12: 45764 | B12: 8-9am | C12: EUR/USD | D12: https://www.tradingview.com/x/GeLcSvKl/ | E12: BUY | F12: WON | G12: 0.006 | H12: Managed SL to protect assets. Hit SL at 0.6% profit | I12: Steve
A13: 45765 | B13: 8-9am | C13: EUR/USD | D13: https://www.tradingview.com/x/ZbAozrlV/ | E13: BUY | F13: WON | G13: 0 | H13: Good Friday: Exited trade due to low volume. Trade would have lost | I13: Steve
A14: 45769 | B14: 8-9am | C14: EUR/USD | D14: https://www.tradingview.com/x/NUysRyod/ | E14: BUY | F14: LOST | G14: -0.01 | I14: Steve
